<?xml version="1.0" ?>
<!-- =================================================================================== -->
<!-- |    This document was autogenerated by xacro from /tmp/buildd/ros-kinetic-hsrb-description-0.18.1/robots/hsrb4s.urdf.xacro | -->
<!-- |    EDITING THIS FILE BY HAND IS NOT RECOMMENDED                                 | -->
<!-- =================================================================================== -->
<robot name="hand_gazebo" xmlns:controller="http://playerstage.sourceforge.net/gazebo/xmlschema/#controller" xmlns:interface="http://playerstage.sourceforge.net/gazebo/xmlschema/#interface" xmlns:sensor="http://playerstage.sourceforge.net/gazebo/xmlschema/#sensor" xmlns:xacro="http://ros.org/wiki/xacro">
  <material name="body_main">
    <color rgba="1.0 0.0 0.0 1.0"/>
  </material>
  <material name="body_sub">
    <color rgba="0.33 0.33 0.33 1.0"/>
  </material>
  <material name="wheel">
    <color rgba="0.2 0.2 0.2 1.0"/>
  </material>
  <material name="black">
    <color rgba="0.1 0.1 0.1 1.0"/>
  </material>
  <material name="tablet">
    <color rgba="0.1 0.1 0.2 1.0"/>
  </material>
  
  <link name="world"/>

  <joint name="world_joint" type="prismatic"> <!-- prismatic-->
    <axis xyz="0.0 0.0 1.0"/>
    <origin rpy="0.0 3.14159265359 0.0" xyz="0.0 0.0 0.3"/>
    <limit effort="100000.0" lower="-5" upper="5" velocity="1.0"/>
    <parent link="world"/>
    <child link="wrist_roll_link"/>
  </joint>

  <link name="wrist_roll_link"/>
  
  <joint name="hand_palm_joint" type="fixed">
    <origin rpy="0.0 0.0 3.14159265359" xyz="0.012 0.0 0.1405"/>
    <parent link="wrist_roll_link"/>
    <child link="hand_palm_link"/>
  </joint>
  <link name="hand_palm_link">
    <inertial>
      <mass value="0.15"/>
      <inertia ixx="0.015" ixy="0.0" ixz="0.0" iyy="0.015" iyz="0.0" izz="0.015"/>
    </inertial>
    <visual>
      <geometry>
        <mesh filename="package://hsrb_description/meshes/hand_v0/palm_light.dae"/>
      </geometry>
    </visual>
    <collision>
      <geometry>
        <mesh filename="package://hsrb_description/meshes/hand_v0/palm.stl"/>
      </geometry>
    </collision>
  </link>
  <joint name="hand_motor_joint" type="revolute">
    <axis xyz="1.0 0.0 0.0"/>
    <limit effort="100.0" lower="-0.798" upper="1.24" velocity="1.0"/>
    <parent link="hand_palm_link"/>
    <child link="hand_motor_dummy_link"/>
    <dynamics damping="0.0001"/>
  </joint>
  <link name="hand_motor_dummy_link">
    <inertial>
      <mass value="0.01"/>
      <inertia ixx="0.0015" ixy="0.0" ixz="0.0" iyy="0.0015" iyz="0.0" izz="0.0015"/>
    </inertial>
  </link>
  <joint name="hand_l_proximal_joint" type="revolute">
    <origin rpy="0.0 0.0 0.0" xyz="-0.01675 -0.0245 -0.0175"/>
    <axis xyz="1.0 0.0 0.0"/>
    <limit effort="100.0" lower="-0.798" upper="1.24" velocity="1.0"/>
    <parent link="hand_palm_link"/>
    <child link="hand_l_proximal_link"/>
    <mimic joint="hand_motor_joint"/>
    <dynamics damping="0.0001"/>
  </joint>
  <link name="hand_l_proximal_link">
    <inertial>
      <mass value="0.01"/>
      <inertia ixx="0.0015" ixy="0.0" ixz="0.0" iyy="0.0015" iyz="0.0" izz="0.0015"/>
    </inertial>
  </link>
  <joint name="hand_l_spring_proximal_joint" type="revolute">
    <axis xyz="1.0 0.0 0.0"/>
    <limit effort="10.0" lower="0.0" upper="0.698" velocity="1.0"/>
    <parent link="hand_l_proximal_link"/>
    <child link="hand_l_spring_proximal_link"/>
    <dynamics damping="0.0001"/>
  </joint>
  <link name="hand_l_spring_proximal_link">
    <inertial>
      <mass value="0.043589"/>
      <origin xyz="0.021418 0.00248 0.022688"/>
      <inertia ixx="0.000026033886" ixy="-0.000000144078" ixz="-0.00000198241" iyy="0.000028824811" iyz="-0.000001268421" izz="0.000005135919"/>
    </inertial>
    <visual>
      <geometry>
        <mesh filename="package://hsrb_description/meshes/hand_v0/l_proximal.dae"/>
      </geometry>
    </visual>
    <collision>
      <geometry>
        <mesh filename="package://hsrb_description/meshes/hand_v0/l_proximal.stl"/>
      </geometry>
    </collision>
  </link>
  <joint name="hand_l_mimic_distal_joint" type="revolute">
    <origin xyz="0.0 0.0 0.07"/>
    <axis xyz="1.0 0.0 0.0"/>
    <limit effort="100.0" lower="-0.698" upper="-0.0" velocity="1.0"/>
    <parent link="hand_l_spring_proximal_link"/>
    <child link="hand_l_mimic_distal_link"/>
    <mimic joint="hand_l_spring_proximal_joint" multiplier="-1.0"/>
    <dynamics damping="0.0001"/>
  </joint>
  <link name="hand_l_mimic_distal_link">
    <inertial>
      <mass value="0.01"/>
      <inertia ixx="0.0015" ixy="0.0" ixz="0.0" iyy="0.0015" iyz="0.0" izz="0.0015"/>
    </inertial>
  </link>
  <joint name="hand_l_distal_joint" type="revolute">
    <axis xyz="1.0 0.0 0.0"/>
    <limit effort="100.0" lower="-1.24" upper="0.798" velocity="1.0"/>
    <parent link="hand_l_mimic_distal_link"/>
    <child link="hand_l_distal_link"/>
    <mimic joint="hand_motor_joint" multiplier="-1.0" offset="-0.087"/>
    <dynamics damping="0.0001"/>
  </joint>
  <link name="hand_l_distal_link">
    <inertial>
      <mass value="0.027731"/>
      <origin xyz="0.011116 0.005679 0.017532"/>
      <inertia ixx="0.000004451952" ixy="-0.000000617574" ixz="0.000000503765" iyy="0.000000503765" iyz="-0.000000435048" izz="0.000004456764"/>
    </inertial>
    <visual>
      <geometry>
        <mesh filename="package://hsrb_description/meshes/hand_v0/l_distal.dae"/>
      </geometry>
    </visual>
    <collision>
      <geometry>
        <mesh filename="package://hsrb_description/meshes/hand_v0/l_distal.stl"/>
      </geometry>
    </collision>
  </link>
  <joint name="hand_l_finger_tip_frame_joint" type="fixed">
    <origin rpy="-1.57079632679 0.0 0.0" xyz="0.01675 0.01865 0.04289"/>
    <parent link="hand_l_distal_link"/>
    <child link="hand_l_finger_tip_frame"/>
    <dynamics damping="0.0001"/>
  </joint>
  <link name="hand_l_finger_tip_frame">
    <inertial>
      <mass value="0.01"/>
      <inertia ixx="0.0015" ixy="0.0" ixz="0.0" iyy="0.0015" iyz="0.0" izz="0.0015"/>
    </inertial>
  </link>
  <joint name="hand_l_finger_vacuum_frame_joint" type="fixed">
    <origin rpy="0.785398163397 0.0 0.0" xyz="0.00475 -0.011539 0.03322"/>
    <parent link="hand_l_distal_link"/>
    <child link="hand_l_finger_vacuum_frame"/>
  </joint>
  <link name="hand_l_finger_vacuum_frame">
    <inertial>
      <mass value="0.01"/>
      <inertia ixx="0.0015" ixy="0.0" ixz="0.0" iyy="0.0015" iyz="0.0" izz="0.0015"/>
    </inertial>
    <visual>
      <origin rpy="0.0 0.0 0.0" xyz="0.0 0.0 -0.01"/>
      <geometry>
        <box size="0.008 0.008 0.02"/>
      </geometry>
      <material name="body_sub"/>
    </visual>
  </link>
  <joint name="hand_r_proximal_joint" type="revolute">
    <origin rpy="0.0 0.0 0.0" xyz="-0.01675 0.0245 -0.0175"/>
    <axis xyz="-1.0 0.0 0.0"/>
    <limit effort="100.0" lower="-0.798" upper="1.24" velocity="1.0"/>
    <parent link="hand_palm_link"/>
    <child link="hand_r_proximal_link"/>
    <mimic joint="hand_motor_joint"/>
    <dynamics damping="0.0001"/>
  </joint>
  <link name="hand_r_proximal_link">
    <inertial>
      <mass value="0.01"/>
      <inertia ixx="0.0015" ixy="0.0" ixz="0.0" iyy="0.0015" iyz="0.0" izz="0.0015"/>
    </inertial>
  </link>
  <joint name="hand_r_spring_proximal_joint" type="revolute">
    <axis xyz="-1.0 0.0 0.0"/>
    <limit effort="10.0" lower="0.0" upper="0.698" velocity="1.0"/>
    <parent link="hand_r_proximal_link"/>
    <child link="hand_r_spring_proximal_link"/>
    <dynamics damping="0.0001"/>
  </joint>
  <link name="hand_r_spring_proximal_link">
    <inertial>
      <mass value="0.043956"/>
      <origin xyz="0.013203 0.002096 0.023311"/>
      <inertia ixx="0.00002623664" ixy="0.00000001631" ixz="0.000001281845" iyy="0.000028838232" iyz="-0.000001621709" izz="0.000004957151"/>
    </inertial>
    <visual>
      <geometry>
        <mesh filename="package://hsrb_description/meshes/hand_v0/r_proximal.dae"/>
      </geometry>
    </visual>
    <collision>
      <geometry>
        <mesh filename="package://hsrb_description/meshes/hand_v0/r_proximal.stl"/>
      </geometry>
    </collision>
  </link>
  <joint name="hand_r_mimic_distal_joint" type="revolute">
    <origin xyz="0.0 0.0 0.07"/>
    <axis xyz="-1.0 0.0 0.0"/>
    <limit effort="100.0" lower="-0.698" upper="-0.0" velocity="1.0"/>
    <parent link="hand_r_spring_proximal_link"/>
    <child link="hand_r_mimic_distal_link"/>
    <mimic joint="hand_r_spring_proximal_joint" multiplier="-1.0"/>
    <dynamics damping="0.0001"/>
  </joint>
  <link name="hand_r_mimic_distal_link">
    <inertial>
      <mass value="0.01"/>
      <inertia ixx="0.0015" ixy="0.0" ixz="0.0" iyy="0.0015" iyz="0.0" izz="0.0015"/>
    </inertial>
  </link>
  <joint name="hand_r_distal_joint" type="revolute">
    <axis xyz="-1.0 0.0 0.0"/>
    <limit effort="100.0" lower="-1.24" upper="0.798" velocity="1.0"/>
    <parent link="hand_r_mimic_distal_link"/>
    <child link="hand_r_distal_link"/>
    <mimic joint="hand_motor_joint" multiplier="-1.0" offset="-0.087"/>
    <dynamics damping="0.0001"/>
  </joint>
  <link name="hand_r_distal_link">
    <inertial>
      <mass value="0.020927"/>
      <origin xyz="0.014256 -0.008321 0.015591"/>
      <inertia ixx="0.00000307518" ixy="-0.00000004954" ixz="0.000000009481" iyy="0.000004074079" iyz="0.000000843648" izz="0.000002807795"/>
    </inertial>
    <visual>
      <geometry>
        <mesh filename="package://hsrb_description/meshes/hand_v0/r_distal.dae"/>
      </geometry>
    </visual>
    <collision>
      <geometry>
        <mesh filename="package://hsrb_description/meshes/hand_v0/r_distal.stl"/>
      </geometry>
    </collision>
  </link>
  <joint name="hand_r_finger_tip_frame_joint" type="fixed">
    <origin rpy="1.57079632679 0.0 0.0" xyz="0.01675 -0.01865 0.04289"/>
    <parent link="hand_r_distal_link"/>
    <child link="hand_r_finger_tip_frame"/>
  </joint>
  <link name="hand_r_finger_tip_frame">
    <inertial>
      <mass value="0.01"/>
      <inertia ixx="0.0015" ixy="0.0" ixz="0.0" iyy="0.0015" iyz="0.0" izz="0.0015"/>
    </inertial>
  </link>


  <gazebo reference="wrist_roll_link">
    <selfCollide>false</selfCollide>
    <gravity>false</gravity>
    <mu1>0.9</mu1>
    <mu2>0.9</mu2>
  </gazebo>
  
  <gazebo reference="hand_palm_link">
    <selfCollide>false</selfCollide>
    <gravity>true</gravity>
    <mu1>0.9</mu1>
    <mu2>0.9</mu2>
  </gazebo>
  
  <gazebo reference="hand_l_proximal_link">
    <selfCollide>false</selfCollide>
    <gravity>true</gravity>
    <mu1>1.0</mu1>
    <mu2>1.0</mu2>
  </gazebo>
  <gazebo reference="hand_l_spring_proximal_link">
    <selfCollide>false</selfCollide>
    <gravity>true</gravity>
    <mu1>1.0</mu1>
    <mu2>1.0</mu2>
  </gazebo>
  <gazebo reference="hand_l_mimic_distal_link">
    <selfCollide>false</selfCollide>
    <gravity>true</gravity>
    <mu1>1.0</mu1>
    <mu2>1.0</mu2>
  </gazebo>
  <gazebo reference="hand_l_distal_link">
    <selfCollide>false</selfCollide>
    <gravity>true</gravity>
    <mu1>1.0</mu1>
    <mu2>1.0</mu2>
  </gazebo>
  <gazebo reference="hand_l_finger_tip_frame">
    <selfCollide>false</selfCollide>
    <gravity>false</gravity>
    <mu1>1.0</mu1>
    <mu2>1.0</mu2>
  </gazebo>
  <gazebo reference="hand_l_finger_vacuum_frame">
    <selfCollide>false</selfCollide>
    <gravity>false</gravity>
    <mu1>1.0</mu1>
    <mu2>1.0</mu2>
  </gazebo>
  <gazebo reference="hand_r_proximal_link">
    <selfCollide>false</selfCollide>
    <gravity>true</gravity>
    <mu1>1.0</mu1>
    <mu2>1.0</mu2>
  </gazebo>
  <gazebo reference="hand_r_spring_proximal_link">
    <selfCollide>false</selfCollide>
    <gravity>true</gravity>
    <mu1>1.0</mu1>
    <mu2>1.0</mu2>
  </gazebo>
  <gazebo reference="hand_r_mimic_distal_link">
    <selfCollide>false</selfCollide>
    <gravity>true</gravity>
    <mu1>1.0</mu1>
    <mu2>1.0</mu2>
  </gazebo>
  <gazebo reference="hand_r_distal_link">
    <selfCollide>false</selfCollide>
    <gravity>false</gravity>
    <mu1>1.0</mu1>
    <mu2>1.0</mu2>
  </gazebo>
  <gazebo reference="hand_r_finger_tip_frame">
    <selfCollide>false</selfCollide>
    <gravity>false</gravity>
    <mu1>1.0</mu1>
    <mu2>1.0</mu2>
  </gazebo>
  
  <gazebo reference="hand_palm_joint">
  </gazebo>
  <gazebo reference="hand_motor_joint">
  </gazebo>
  <gazebo reference="hand_l_proximal_joint">
  </gazebo>
  <gazebo reference="hand_l_spring_proximal_joint">
  </gazebo>
  <gazebo reference="hand_l_mimic_distal_joint">
  </gazebo>
  <gazebo reference="hand_l_distal_joint">
  </gazebo>
  <gazebo reference="hand_r_proximal_joint">
  </gazebo>
  <gazebo reference="hand_r_spring_proximal_joint">
  </gazebo>
  <gazebo reference="hand_r_mimic_distal_joint">
  </gazebo>
  <gazebo reference="hand_r_distal_joint">
  </gazebo>
  <gazebo reference="hand_r_distal_joint">
  </gazebo>
  <gazebo reference="world_joint">
  </gazebo>
  

  <gazebo>
    <plugin filename="libtmc_gazebo_hrh_gripper.so" name="hsrb_hrh_gripper_plugin">
      <sensitiveness>0.05</sensitiveness>
      <update_rate>1000.0</update_rate>
      <max_torque>8.0</max_torque>
      <!-- 5[deg] -->
      <error_tolerance>0.0872</error_tolerance>
      <stall_timeout>2.0</stall_timeout>
    </plugin>    
    <plugin filename="libhsrb_grasp_hack.so" name="hsrb_grasp_hack_plugin">
      <grasp_check>
        <attach_steps>1</attach_steps>
        <detach_steps>2</detach_steps>
        <min_contact_count>1</min_contact_count>
        <max_attach_weight>1.2</max_attach_weight>
      </grasp_check>
      <gripper_link>hand_r_distal_link</gripper_link>
      <gripper_link>hand_l_distal_link</gripper_link>
      <gripper_link>hand_r_spring_proximal_link</gripper_link>
      <gripper_link>hand_l_spring_proximal_link</gripper_link>
      <!-- hand_palm_link is merged with wrist_ft_sensor_frame by fixed joint  -->
      <palm_link>wrist_roll_link</palm_link>
    </plugin>
  </gazebo>
  
  <transmission name="world_joint_transmission">
    <type>transmission_interface/SimpleTransmission</type>
    <joint name="world_joint">
      <hardwareInterface>hardware_interface/EffortJointInterface</hardwareInterface>
    </joint>
    <actuator name="world_joint_actuator">
      <hardwareInterface>hardware_interface/EffortJointInterface</hardwareInterface>
      <mechanicalReduction>1</mechanicalReduction>
    </actuator>
  </transmission>

 <transmission name="hand_l_joint_transmission">
    <type>transmission_interface/SimpleTransmission</type>
    <joint name="hand_l_proximal_joint">
      <hardwareInterface>hardware_interface/EffortJointInterface</hardwareInterface>
    </joint>
    <actuator name="hand_l_proximal_joint_actuator">
      <hardwareInterface>hardware_interface/EffortJointInterface</hardwareInterface>
      <mechanicalReduction>1</mechanicalReduction>
    </actuator>
  </transmission>
 <transmission name="hand_r_joint_transmission">
    <type>transmission_interface/SimpleTransmission</type>
    <joint name="hand_r_proximal_joint">
      <hardwareInterface>hardware_interface/EffortJointInterface</hardwareInterface>
    </joint>
    <actuator name="hand_r_proximal_joint_actuator">
      <hardwareInterface>hardware_interface/EffortJointInterface</hardwareInterface>
      <mechanicalReduction>1</mechanicalReduction>
    </actuator>
  </transmission>

  <transmission name="hand_motor_joint_transmission">
    <type>transmission_interface/SimpleTransmission</type>
    <joint name="hand_motor_joint">
      <hardwareInterface>hardware_interface/EffortJointInterface</hardwareInterface>
    </joint>
    <actuator name="hand_motor_joint_actuator">
      <hardwareInterface>hardware_interface/EffortJointInterface</hardwareInterface>
      <mechanicalReduction>1</mechanicalReduction>
    </actuator>
  </transmission>
  <transmission name="hand_l_spring_proximal_joint_transmission">
    <type>transmission_interface/SimpleTransmission</type>
    <joint name="hand_l_spring_proximal_joint">
      <hardwareInterface>hardware_interface/EffortJointInterface</hardwareInterface>
    </joint>
    <actuator name="hand_l_spring_proximal_joint_actuator">
      <hardwareInterface>hardware_interface/EffortJointInterface</hardwareInterface>
      <mechanicalReduction>1</mechanicalReduction>
    </actuator>
  </transmission>
  <transmission name="hand_r_spring_proximal_joint_transmission">
    <type>transmission_interface/SimpleTransmission</type>
    <joint name="hand_r_spring_proximal_joint">
      <hardwareInterface>hardware_interface/EffortJointInterface</hardwareInterface>
    </joint>
    <actuator name="hand_r_spring_proximal_joint_actuator">
      <hardwareInterface>hardware_interface/EffortJointInterface</hardwareInterface>
      <mechanicalReduction>1</mechanicalReduction>
    </actuator>
  </transmission>
  <gazebo>
    <plugin name="gazebo_ros_control" filename="libhsrb_gazebo_ros_control.so">
      <robotNamespace>hand_gazebo</robotNamespace>
      <legacyModeNS>true</legacyModeNS>
    </plugin>
  </gazebo>

</robot>

